=== TESTE COMPLETO DO BUILDER ===
Traceback (most recent call last):
  File "C:\Users\familia\AppData\Roaming\Python\Python312\site-packages\django\db\models\fields\__init__.py", line 2123, in get_prep_value
    return int(value)
           ^^^^^^^^^^
TypeError: int() argument must be a string, a bytes-like object or a real number, not 'Empresa'

The above exception was the direct cause of the following exception:

Traceback (most recent call last):
  File "f:\Projects\Django\prj_medicos\teste_final_builder.py", line 19, in <module>
    dados = montar_relatorio_mensal_socio(empresa, socio, competencia)
            ^^^^^^^^^^^^^^^^^^^^^^^^^^^^^^^^^^^^^^^^^^^^^^^^^^^^^^^^^^
  File "f:\Projects\Django\prj_medicos\medicos\relatorios\builders.py", line 31, in montar_relatorio_mensal_socio
    empresa = Empresa.objects.get(id=empresa_id)
              ^^^^^^^^^^^^^^^^^^^^^^^^^^^^^^^^^^
  File "C:\Users\familia\AppData\Roaming\Python\Python312\site-packages\django\db\models\manager.py", line 87, in manager_method
    return getattr(self.get_queryset(), name)(*args, **kwargs)
           ^^^^^^^^^^^^^^^^^^^^^^^^^^^^^^^^^^^^^^^^^^^^^^^^^^^
  File "C:\Users\familia\AppData\Roaming\Python\Python312\site-packages\django\db\models\query.py", line 635, in get
    clone = self._chain() if self.query.combinator else self.filter(*args, **kwargs)
                                                        ^^^^^^^^^^^^^^^^^^^^^^^^^^^^
  File "C:\Users\familia\AppData\Roaming\Python\Python312\site-packages\django\db\models\query.py", line 1476, in filter
    return self._filter_or_exclude(False, args, kwargs)
           ^^^^^^^^^^^^^^^^^^^^^^^^^^^^^^^^^^^^^^^^^^^^
  File "C:\Users\familia\AppData\Roaming\Python\Python312\site-packages\django\db\models\query.py", line 1494, in _filter_or_exclude
    clone._filter_or_exclude_inplace(negate, args, kwargs)
  File "C:\Users\familia\AppData\Roaming\Python\Python312\site-packages\django\db\models\query.py", line 1501, in _filter_or_exclude_inplace
    self._query.add_q(Q(*args, **kwargs))
  File "C:\Users\familia\AppData\Roaming\Python\Python312\site-packages\django\db\models\sql\query.py", line 1609, in add_q
    clause, _ = self._add_q(q_object, self.used_aliases)
                ^^^^^^^^^^^^^^^^^^^^^^^^^^^^^^^^^^^^^^^^
  File "C:\Users\familia\AppData\Roaming\Python\Python312\site-packages\django\db\models\sql\query.py", line 1641, in _add_q
    child_clause, needed_inner = self.build_filter(
                                 ^^^^^^^^^^^^^^^^^^
  File "C:\Users\familia\AppData\Roaming\Python\Python312\site-packages\django\db\models\sql\query.py", line 1555, in build_filter
    condition = self.build_lookup(lookups, col, value)
                ^^^^^^^^^^^^^^^^^^^^^^^^^^^^^^^^^^^^^^
  File "C:\Users\familia\AppData\Roaming\Python\Python312\site-packages\django\db\models\sql\query.py", line 1385, in build_lookup
    lookup = lookup_class(lhs, rhs)
             ^^^^^^^^^^^^^^^^^^^^^^
  File "C:\Users\familia\AppData\Roaming\Python\Python312\site-packages\django\db\models\lookups.py", line 30, in __init__
    self.rhs = self.get_prep_lookup()
               ^^^^^^^^^^^^^^^^^^^^^^
  File "C:\Users\familia\AppData\Roaming\Python\Python312\site-packages\django\db\models\lookups.py", line 369, in get_prep_lookup
    return super().get_prep_lookup()
           ^^^^^^^^^^^^^^^^^^^^^^^^^
  File "C:\Users\familia\AppData\Roaming\Python\Python312\site-packages\django\db\models\lookups.py", line 88, in get_prep_lookup
    return self.lhs.output_field.get_prep_value(self.rhs)
           ^^^^^^^^^^^^^^^^^^^^^^^^^^^^^^^^^^^^^^^^^^^^^^
  File "C:\Users\familia\AppData\Roaming\Python\Python312\site-packages\django\db\models\fields\__init__.py", line 2125, in get_prep_value
    raise e.__class__(
TypeError: Field 'id' expected a number but got <Empresa: Clinica de Todos>.
